2020-04-19 01:02:38,835 INFO: Microblog startup [in C:\Users\User\Desktop\PythonTest\microblog\app\__init__.py:45]
2020-04-19 01:02:54,957 ERROR: Exception on /edit_profile [POST] [in C:\Users\User\Anaconda3\envs\vnev\lib\site-packages\flask\app.py:1891]
Traceback (most recent call last):
  File "C:\Users\User\Anaconda3\envs\vnev\lib\site-packages\flask\app.py", line 2446, in wsgi_app
    response = self.full_dispatch_request()
  File "C:\Users\User\Anaconda3\envs\vnev\lib\site-packages\flask\app.py", line 1951, in full_dispatch_request
    rv = self.handle_user_exception(e)
  File "C:\Users\User\Anaconda3\envs\vnev\lib\site-packages\flask\app.py", line 1820, in handle_user_exception
    reraise(exc_type, exc_value, tb)
  File "C:\Users\User\Anaconda3\envs\vnev\lib\site-packages\flask\_compat.py", line 39, in reraise
    raise value
  File "C:\Users\User\Anaconda3\envs\vnev\lib\site-packages\flask\app.py", line 1949, in full_dispatch_request
    rv = self.dispatch_request()
  File "C:\Users\User\Anaconda3\envs\vnev\lib\site-packages\flask\app.py", line 1935, in dispatch_request
    return self.view_functions[rule.endpoint](**req.view_args)
  File "C:\Users\User\Anaconda3\envs\vnev\lib\site-packages\flask_login\utils.py", line 261, in decorated_view
    return func(*args, **kwargs)
  File "C:\Users\User\Desktop\PythonTest\microblog\app\routes.py", line 89, in edit_profile
    if form.validate_on_submit():
  File "C:\Users\User\Anaconda3\envs\vnev\lib\site-packages\flask_wtf\form.py", line 100, in validate_on_submit
    return self.is_submitted() and self.validate()
  File "C:\Users\User\Anaconda3\envs\vnev\lib\site-packages\wtforms\form.py", line 310, in validate
    return super(Form, self).validate(extra)
  File "C:\Users\User\Anaconda3\envs\vnev\lib\site-packages\wtforms\form.py", line 152, in validate
    if not field.validate(self, extra):
  File "C:\Users\User\Anaconda3\envs\vnev\lib\site-packages\wtforms\fields\core.py", line 206, in validate
    stop_validation = self._run_validation_chain(form, chain)
  File "C:\Users\User\Anaconda3\envs\vnev\lib\site-packages\wtforms\fields\core.py", line 226, in _run_validation_chain
    validator(form, self)
  File "C:\Users\User\Desktop\PythonTest\microblog\app\forms.py", line 43, in validate_username
    raise ValidationError('Please use a different username.')
NameError: name 'ValidationError' is not defined
2020-04-19 01:05:21,056 ERROR: Exception on /register [POST] [in C:\Users\User\Anaconda3\envs\vnev\lib\site-packages\flask\app.py:1891]
Traceback (most recent call last):
  File "C:\Users\User\Anaconda3\envs\vnev\lib\site-packages\flask\app.py", line 2446, in wsgi_app
    response = self.full_dispatch_request()
  File "C:\Users\User\Anaconda3\envs\vnev\lib\site-packages\flask\app.py", line 1951, in full_dispatch_request
    rv = self.handle_user_exception(e)
  File "C:\Users\User\Anaconda3\envs\vnev\lib\site-packages\flask\app.py", line 1820, in handle_user_exception
    reraise(exc_type, exc_value, tb)
  File "C:\Users\User\Anaconda3\envs\vnev\lib\site-packages\flask\_compat.py", line 39, in reraise
    raise value
  File "C:\Users\User\Anaconda3\envs\vnev\lib\site-packages\flask\app.py", line 1949, in full_dispatch_request
    rv = self.dispatch_request()
  File "C:\Users\User\Anaconda3\envs\vnev\lib\site-packages\flask\app.py", line 1935, in dispatch_request
    return self.view_functions[rule.endpoint](**req.view_args)
  File "C:\Users\User\Desktop\PythonTest\microblog\app\routes.py", line 62, in register
    if form1.validate_on_submit():
  File "C:\Users\User\Anaconda3\envs\vnev\lib\site-packages\flask_wtf\form.py", line 100, in validate_on_submit
    return self.is_submitted() and self.validate()
  File "C:\Users\User\Anaconda3\envs\vnev\lib\site-packages\wtforms\form.py", line 310, in validate
    return super(Form, self).validate(extra)
  File "C:\Users\User\Anaconda3\envs\vnev\lib\site-packages\wtforms\form.py", line 152, in validate
    if not field.validate(self, extra):
  File "C:\Users\User\Anaconda3\envs\vnev\lib\site-packages\wtforms\fields\core.py", line 206, in validate
    stop_validation = self._run_validation_chain(form, chain)
  File "C:\Users\User\Anaconda3\envs\vnev\lib\site-packages\wtforms\fields\core.py", line 226, in _run_validation_chain
    validator(form, self)
  File "C:\Users\User\Desktop\PythonTest\microblog\app\forms.py", line 23, in validate_username
    raise ValidationError('Please use another username')
NameError: name 'ValidationError' is not defined
2020-04-19 01:06:58,739 INFO: Microblog startup [in C:\Users\User\Desktop\PythonTest\microblog\app\__init__.py:45]
2020-04-19 15:55:34,305 INFO: Microblog startup [in C:\Users\User\Desktop\PythonTest\microblog\app\__init__.py:45]
2020-04-19 15:56:04,100 INFO: Microblog startup [in C:\Users\User\Desktop\PythonTest\microblog\app\__init__.py:45]
2020-04-19 18:07:20,791 INFO: Microblog startup [in C:\Users\User\Desktop\PythonTest\microblog\app\__init__.py:45]
2020-04-19 18:30:30,265 INFO: Microblog startup [in C:\Users\User\Desktop\PythonTest\microblog\app\__init__.py:45]
2020-04-19 18:30:50,938 ERROR: Exception on /follow/anona [GET] [in C:\Users\User\Anaconda3\envs\vnev\lib\site-packages\flask\app.py:1891]
Traceback (most recent call last):
  File "C:\Users\User\Anaconda3\envs\vnev\lib\site-packages\flask\app.py", line 2446, in wsgi_app
    response = self.full_dispatch_request()
  File "C:\Users\User\Anaconda3\envs\vnev\lib\site-packages\flask\app.py", line 1951, in full_dispatch_request
    rv = self.handle_user_exception(e)
  File "C:\Users\User\Anaconda3\envs\vnev\lib\site-packages\flask\app.py", line 1820, in handle_user_exception
    reraise(exc_type, exc_value, tb)
  File "C:\Users\User\Anaconda3\envs\vnev\lib\site-packages\flask\_compat.py", line 39, in reraise
    raise value
  File "C:\Users\User\Anaconda3\envs\vnev\lib\site-packages\flask\app.py", line 1949, in full_dispatch_request
    rv = self.dispatch_request()
  File "C:\Users\User\Anaconda3\envs\vnev\lib\site-packages\flask\app.py", line 1935, in dispatch_request
    return self.view_functions[rule.endpoint](**req.view_args)
  File "C:\Users\User\Anaconda3\envs\vnev\lib\site-packages\flask_login\utils.py", line 261, in decorated_view
    return func(*args, **kwargs)
  File "C:\Users\User\Desktop\PythonTest\microblog\app\routes.py", line 108, in follow
    if user == cureent_user:
NameError: name 'cureent_user' is not defined
2020-04-19 18:31:15,912 INFO: Microblog startup [in C:\Users\User\Desktop\PythonTest\microblog\app\__init__.py:45]
2020-04-19 18:42:09,681 INFO: Microblog startup [in C:\Users\User\Desktop\PythonTest\microblog\app\__init__.py:45]
2020-04-19 21:28:37,269 INFO: Microblog startup [in C:\Users\User\Desktop\PythonTest\microblog\app\__init__.py:45]
2020-04-19 21:28:44,666 INFO: Microblog startup [in C:\Users\User\Desktop\PythonTest\microblog\app\__init__.py:45]
2020-04-19 21:32:11,922 INFO: Microblog startup [in C:\Users\User\Desktop\PythonTest\microblog\app\__init__.py:45]
2020-04-19 22:25:24,576 INFO: Microblog startup [in C:\Users\User\Desktop\PythonTest\microblog\app\__init__.py:45]
2020-04-19 22:48:21,059 INFO: Microblog startup [in C:\Users\User\Desktop\PythonTest\microblog\app\__init__.py:45]
2020-04-19 22:56:34,715 INFO: Microblog startup [in C:\Users\User\Desktop\PythonTest\microblog\app\__init__.py:45]
2020-04-19 22:56:38,125 ERROR: Exception on /user/james [GET] [in C:\Users\User\Anaconda3\envs\vnev\lib\site-packages\flask\app.py:1891]
Traceback (most recent call last):
  File "C:\Users\User\Anaconda3\envs\vnev\lib\site-packages\flask\app.py", line 2446, in wsgi_app
    response = self.full_dispatch_request()
  File "C:\Users\User\Anaconda3\envs\vnev\lib\site-packages\flask\app.py", line 1951, in full_dispatch_request
    rv = self.handle_user_exception(e)
  File "C:\Users\User\Anaconda3\envs\vnev\lib\site-packages\flask\app.py", line 1820, in handle_user_exception
    reraise(exc_type, exc_value, tb)
  File "C:\Users\User\Anaconda3\envs\vnev\lib\site-packages\flask\_compat.py", line 39, in reraise
    raise value
  File "C:\Users\User\Anaconda3\envs\vnev\lib\site-packages\flask\app.py", line 1949, in full_dispatch_request
    rv = self.dispatch_request()
  File "C:\Users\User\Anaconda3\envs\vnev\lib\site-packages\flask\app.py", line 1935, in dispatch_request
    return self.view_functions[rule.endpoint](**req.view_args)
  File "C:\Users\User\Anaconda3\envs\vnev\lib\site-packages\flask_login\utils.py", line 261, in decorated_view
    return func(*args, **kwargs)
  File "C:\Users\User\Desktop\PythonTest\microblog\app\routes.py", line 96, in user
    page, app.config['POSTS_PER_PAGE'], False)
KeyError: 'POSTS_PER_PAGE'
2020-04-19 22:56:54,600 INFO: Microblog startup [in C:\Users\User\Desktop\PythonTest\microblog\app\__init__.py:45]
2020-04-19 22:56:59,525 INFO: Microblog startup [in C:\Users\User\Desktop\PythonTest\microblog\app\__init__.py:45]
2020-04-19 23:02:16,533 INFO: Microblog startup [in C:\Users\User\Desktop\PythonTest\microblog\app\__init__.py:45]
2020-04-20 00:15:25,189 INFO: Microblog startup [in C:\Users\User\Desktop\PythonTest\microblog\app\__init__.py:47]
2020-04-20 00:15:49,213 INFO: Microblog startup [in C:\Users\User\Desktop\PythonTest\microblog\app\__init__.py:47]
2020-04-20 00:16:30,770 INFO: Microblog startup [in C:\Users\User\Desktop\PythonTest\microblog\app\__init__.py:47]
2020-04-20 01:00:37,354 INFO: Microblog startup [in C:\Users\User\Desktop\PythonTest\microblog\app\__init__.py:49]
2020-04-20 20:13:22,383 INFO: Microblog startup [in C:\Users\User\Desktop\PythonTest\microblog\app\__init__.py:49]
2020-04-20 22:48:19,958 INFO: Microblog startup [in C:\Users\User\Desktop\PythonTest\microblog\app\__init__.py:49]
2020-04-20 22:49:44,319 INFO: Microblog startup [in C:\Users\User\Desktop\PythonTest\microblog\app\__init__.py:49]
2020-04-20 22:51:00,854 INFO: Microblog startup [in C:\Users\User\Desktop\PythonTest\microblog\app\__init__.py:49]
2020-04-20 22:52:47,956 INFO: Microblog startup [in C:\Users\User\Desktop\PythonTest\microblog\app\__init__.py:49]
