2020-04-25 16:54:25,029 ERROR: Exception on /index [GET] [in C:\Users\User\Anaconda3\envs\vnev\lib\site-packages\flask\app.py:1891]
Traceback (most recent call last):
  File "C:\Users\User\Anaconda3\envs\vnev\lib\site-packages\flask\app.py", line 2446, in wsgi_app
    response = self.full_dispatch_request()
  File "C:\Users\User\Anaconda3\envs\vnev\lib\site-packages\flask\app.py", line 1951, in full_dispatch_request
    rv = self.handle_user_exception(e)
  File "C:\Users\User\Anaconda3\envs\vnev\lib\site-packages\flask\app.py", line 1820, in handle_user_exception
    reraise(exc_type, exc_value, tb)
  File "C:\Users\User\Anaconda3\envs\vnev\lib\site-packages\flask\_compat.py", line 39, in reraise
    raise value
  File "C:\Users\User\Anaconda3\envs\vnev\lib\site-packages\flask\app.py", line 1949, in full_dispatch_request
    rv = self.dispatch_request()
  File "C:\Users\User\Anaconda3\envs\vnev\lib\site-packages\flask\app.py", line 1935, in dispatch_request
    return self.view_functions[rule.endpoint](**req.view_args)
  File "C:\Users\User\Anaconda3\envs\vnev\lib\site-packages\flask_login\utils.py", line 261, in decorated_view
    return func(*args, **kwargs)
  File "C:\Users\User\Desktop\PythonTest\microblog\app\routes.py", line 29, in index
    prev_url=prev_url)
  File "C:\Users\User\Anaconda3\envs\vnev\lib\site-packages\flask\templating.py", line 140, in render_template
    ctx.app,
  File "C:\Users\User\Anaconda3\envs\vnev\lib\site-packages\flask\templating.py", line 120, in _render
    rv = template.render(context)
  File "C:\Users\User\Anaconda3\envs\vnev\lib\site-packages\jinja2\environment.py", line 1090, in render
    self.environment.handle_exception()
  File "C:\Users\User\Anaconda3\envs\vnev\lib\site-packages\jinja2\environment.py", line 832, in handle_exception
    reraise(*rewrite_traceback_stack(source=source))
  File "C:\Users\User\Anaconda3\envs\vnev\lib\site-packages\jinja2\_compat.py", line 28, in reraise
    raise value.with_traceback(tb)
  File "C:\Users\User\Desktop\PythonTest\microblog\app\../templates\index.html", line 2, in top-level template code
    {% import 'bootstrap/wtf.html' as wtf %}
  File "C:\Users\User\Desktop\PythonTest\microblog\app\../templates\base.html", line 1, in top-level template code
    {% extends 'bootstrap/base.html' %}
  File "C:\Users\User\Anaconda3\envs\vnev\lib\site-packages\flask_bootstrap\templates\bootstrap\base.html", line 1, in top-level template code
    {% block doc -%}
  File "C:\Users\User\Anaconda3\envs\vnev\lib\site-packages\flask_bootstrap\templates\bootstrap\base.html", line 3, in block "doc"
    <html{% block html_attribs %}{% endblock html_attribs %}>
  File "C:\Users\User\Anaconda3\envs\vnev\lib\site-packages\flask_bootstrap\templates\bootstrap\base.html", line 11, in block "html"
    {%- endblock metas %}
  File "C:\Users\User\Anaconda3\envs\vnev\lib\site-packages\flask_bootstrap\templates\bootstrap\base.html", line 12, in block "body"
  File "C:\Users\User\Desktop\PythonTest\microblog\app\../templates\base.html", line 35, in block "navbar"
    action="{{ url_for('main.search') }}">
  File "C:\Users\User\Anaconda3\envs\vnev\lib\site-packages\flask\helpers.py", line 370, in url_for
    return appctx.app.handle_url_build_error(error, endpoint, values)
  File "C:\Users\User\Anaconda3\envs\vnev\lib\site-packages\flask\app.py", line 2215, in handle_url_build_error
    reraise(exc_type, exc_value, tb)
  File "C:\Users\User\Anaconda3\envs\vnev\lib\site-packages\flask\_compat.py", line 39, in reraise
    raise value
  File "C:\Users\User\Anaconda3\envs\vnev\lib\site-packages\flask\helpers.py", line 358, in url_for
    endpoint, values, method=method, force_external=external
  File "C:\Users\User\Anaconda3\envs\vnev\lib\site-packages\werkzeug\routing.py", line 2179, in build
    raise BuildError(endpoint, values, method, self)
werkzeug.routing.BuildError: Could not build url for endpoint 'main.search'. Did you mean 'search' instead?
2020-04-25 16:55:03,427 INFO: Microblog startup [in C:\Users\User\Desktop\PythonTest\microblog\app\__init__.py:54]
2020-04-25 16:55:11,729 ERROR: Exception on /search [GET] [in C:\Users\User\Anaconda3\envs\vnev\lib\site-packages\flask\app.py:1891]
Traceback (most recent call last):
  File "C:\Users\User\Anaconda3\envs\vnev\lib\site-packages\flask\app.py", line 2446, in wsgi_app
    response = self.full_dispatch_request()
  File "C:\Users\User\Anaconda3\envs\vnev\lib\site-packages\flask\app.py", line 1951, in full_dispatch_request
    rv = self.handle_user_exception(e)
  File "C:\Users\User\Anaconda3\envs\vnev\lib\site-packages\flask\app.py", line 1820, in handle_user_exception
    reraise(exc_type, exc_value, tb)
  File "C:\Users\User\Anaconda3\envs\vnev\lib\site-packages\flask\_compat.py", line 39, in reraise
    raise value
  File "C:\Users\User\Anaconda3\envs\vnev\lib\site-packages\flask\app.py", line 1949, in full_dispatch_request
    rv = self.dispatch_request()
  File "C:\Users\User\Anaconda3\envs\vnev\lib\site-packages\flask\app.py", line 1935, in dispatch_request
    return self.view_functions[rule.endpoint](**req.view_args)
  File "C:\Users\User\Anaconda3\envs\vnev\lib\site-packages\flask_login\utils.py", line 261, in decorated_view
    return func(*args, **kwargs)
  File "C:\Users\User\Desktop\PythonTest\microblog\app\routes.py", line 158, in search
    current_app.config['POSTS_PER_PAGE'])
NameError: name 'current_app' is not defined
2020-04-25 16:58:38,936 INFO: Microblog startup [in C:\Users\User\Desktop\PythonTest\microblog\app\__init__.py:54]
2020-04-25 17:00:48,691 INFO: Microblog startup [in C:\Users\User\Desktop\PythonTest\microblog\app\__init__.py:54]
2020-04-25 17:00:49,009 ERROR: Exception on /search [GET] [in C:\Users\User\Anaconda3\envs\vnev\lib\site-packages\flask\app.py:1891]
Traceback (most recent call last):
  File "C:\Users\User\Anaconda3\envs\vnev\lib\site-packages\flask\app.py", line 2446, in wsgi_app
    response = self.full_dispatch_request()
  File "C:\Users\User\Anaconda3\envs\vnev\lib\site-packages\flask\app.py", line 1951, in full_dispatch_request
    rv = self.handle_user_exception(e)
  File "C:\Users\User\Anaconda3\envs\vnev\lib\site-packages\flask\app.py", line 1820, in handle_user_exception
    reraise(exc_type, exc_value, tb)
  File "C:\Users\User\Anaconda3\envs\vnev\lib\site-packages\flask\_compat.py", line 39, in reraise
    raise value
  File "C:\Users\User\Anaconda3\envs\vnev\lib\site-packages\flask\app.py", line 1949, in full_dispatch_request
    rv = self.dispatch_request()
  File "C:\Users\User\Anaconda3\envs\vnev\lib\site-packages\flask\app.py", line 1935, in dispatch_request
    return self.view_functions[rule.endpoint](**req.view_args)
  File "C:\Users\User\Anaconda3\envs\vnev\lib\site-packages\flask_login\utils.py", line 261, in decorated_view
    return func(*args, **kwargs)
  File "C:\Users\User\Desktop\PythonTest\microblog\app\routes.py", line 158, in search
    current_app.config['POSTS_PER_PAGE'])
NameError: name 'current_app' is not defined
2020-04-25 17:03:15,305 INFO: Microblog startup [in C:\Users\User\Desktop\PythonTest\microblog\app\__init__.py:54]
2020-04-25 17:03:22,198 ERROR: Exception on /search [GET] [in C:\Users\User\Anaconda3\envs\vnev\lib\site-packages\flask\app.py:1891]
Traceback (most recent call last):
  File "C:\Users\User\Anaconda3\envs\vnev\lib\site-packages\flask\app.py", line 2446, in wsgi_app
    response = self.full_dispatch_request()
  File "C:\Users\User\Anaconda3\envs\vnev\lib\site-packages\flask\app.py", line 1951, in full_dispatch_request
    rv = self.handle_user_exception(e)
  File "C:\Users\User\Anaconda3\envs\vnev\lib\site-packages\flask\app.py", line 1820, in handle_user_exception
    reraise(exc_type, exc_value, tb)
  File "C:\Users\User\Anaconda3\envs\vnev\lib\site-packages\flask\_compat.py", line 39, in reraise
    raise value
  File "C:\Users\User\Anaconda3\envs\vnev\lib\site-packages\flask\app.py", line 1949, in full_dispatch_request
    rv = self.dispatch_request()
  File "C:\Users\User\Anaconda3\envs\vnev\lib\site-packages\flask\app.py", line 1935, in dispatch_request
    return self.view_functions[rule.endpoint](**req.view_args)
  File "C:\Users\User\Anaconda3\envs\vnev\lib\site-packages\flask_login\utils.py", line 261, in decorated_view
    return func(*args, **kwargs)
  File "C:\Users\User\Desktop\PythonTest\microblog\app\routes.py", line 158, in search
    current_app.config['POSTS_PER_PAGE'])
KeyError: 'POSTS_PER_PAGE'
2020-04-25 17:03:58,469 INFO: Microblog startup [in C:\Users\User\Desktop\PythonTest\microblog\app\__init__.py:54]
2020-04-25 17:08:50,792 INFO: Microblog startup [in C:\Users\User\Desktop\PythonTest\microblog\app\__init__.py:54]
2020-04-25 17:21:10,334 INFO: Microblog startup [in C:\Users\User\Desktop\PythonTest\microblog\app\__init__.py:54]
