2020-04-21 22:41:25,131 INFO: Microblog startup [in C:\Users\User\Desktop\PythonTest\microblog\app\__init__.py:51]
2020-04-21 22:43:13,083 INFO: Microblog startup [in C:\Users\User\Desktop\PythonTest\microblog\app\__init__.py:51]
2020-04-21 22:44:08,929 INFO: Microblog startup [in C:\Users\User\Desktop\PythonTest\microblog\app\__init__.py:51]
2020-04-21 23:38:03,752 INFO: Microblog startup [in C:\Users\User\Desktop\PythonTest\microblog\app\__init__.py:51]
2020-04-22 20:45:04,830 INFO: Microblog startup [in C:\Users\User\Desktop\PythonTest\microblog\app\__init__.py:51]
2020-04-22 23:36:07,496 INFO: Microblog startup [in C:\Users\User\Desktop\PythonTest\microblog\app\__init__.py:51]
2020-04-22 23:36:17,569 INFO: Microblog startup [in C:\Users\User\Desktop\PythonTest\microblog\app\__init__.py:51]
2020-04-23 01:23:44,263 INFO: Microblog startup [in C:\Users\User\Desktop\PythonTest\microblog\app\__init__.py:54]
2020-04-24 00:52:16,811 INFO: Microblog startup [in C:\Users\User\Desktop\PythonTest\microblog\app\__init__.py:54]
2020-04-24 09:28:29,742 INFO: Microblog startup [in C:\Users\User\Desktop\PythonTest\microblog\app\__init__.py:54]
2020-04-25 16:23:30,186 INFO: Microblog startup [in C:\Users\User\Desktop\PythonTest\microblog\app\__init__.py:54]
2020-04-25 16:24:41,134 INFO: Microblog startup [in C:\Users\User\Desktop\PythonTest\microblog\app\__init__.py:54]
2020-04-25 16:52:04,082 INFO: Microblog startup [in C:\Users\User\Desktop\PythonTest\microblog\app\__init__.py:54]
2020-04-25 16:52:16,103 ERROR: Exception on /login [GET] [in C:\Users\User\Anaconda3\envs\vnev\lib\site-packages\flask\app.py:1891]
Traceback (most recent call last):
  File "C:\Users\User\Anaconda3\envs\vnev\lib\site-packages\flask\app.py", line 2446, in wsgi_app
    response = self.full_dispatch_request()
  File "C:\Users\User\Anaconda3\envs\vnev\lib\site-packages\flask\app.py", line 1951, in full_dispatch_request
    rv = self.handle_user_exception(e)
  File "C:\Users\User\Anaconda3\envs\vnev\lib\site-packages\flask\app.py", line 1820, in handle_user_exception
    reraise(exc_type, exc_value, tb)
  File "C:\Users\User\Anaconda3\envs\vnev\lib\site-packages\flask\_compat.py", line 39, in reraise
    raise value
  File "C:\Users\User\Anaconda3\envs\vnev\lib\site-packages\flask\app.py", line 1949, in full_dispatch_request
    rv = self.dispatch_request()
  File "C:\Users\User\Anaconda3\envs\vnev\lib\site-packages\flask\app.py", line 1935, in dispatch_request
    return self.view_functions[rule.endpoint](**req.view_args)
  File "C:\Users\User\Desktop\PythonTest\microblog\app\routes.py", line 58, in login
    return render_template('login.html',title='SignIn',form=form)
  File "C:\Users\User\Anaconda3\envs\vnev\lib\site-packages\flask\templating.py", line 140, in render_template
    ctx.app,
  File "C:\Users\User\Anaconda3\envs\vnev\lib\site-packages\flask\templating.py", line 120, in _render
    rv = template.render(context)
  File "C:\Users\User\Anaconda3\envs\vnev\lib\site-packages\jinja2\environment.py", line 1090, in render
    self.environment.handle_exception()
  File "C:\Users\User\Anaconda3\envs\vnev\lib\site-packages\jinja2\environment.py", line 832, in handle_exception
    reraise(*rewrite_traceback_stack(source=source))
  File "C:\Users\User\Anaconda3\envs\vnev\lib\site-packages\jinja2\_compat.py", line 28, in reraise
    raise value.with_traceback(tb)
  File "C:\Users\User\Desktop\PythonTest\microblog\app\../templates\login.html", line 2, in top-level template code
    {% import 'bootstrap/wtf.html' as wtf %}
  File "C:\Users\User\Desktop\PythonTest\microblog\app\../templates\base.html", line 1, in top-level template code
    {% extends 'bootstrap/base.html' %}
  File "C:\Users\User\Anaconda3\envs\vnev\lib\site-packages\flask_bootstrap\templates\bootstrap\base.html", line 1, in top-level template code
    {% block doc -%}
  File "C:\Users\User\Anaconda3\envs\vnev\lib\site-packages\flask_bootstrap\templates\bootstrap\base.html", line 3, in block "doc"
    <html{% block html_attribs %}{% endblock html_attribs %}>
  File "C:\Users\User\Anaconda3\envs\vnev\lib\site-packages\flask_bootstrap\templates\bootstrap\base.html", line 11, in block "html"
    {%- endblock metas %}
  File "C:\Users\User\Anaconda3\envs\vnev\lib\site-packages\flask_bootstrap\templates\bootstrap\base.html", line 13, in block "body"
    {%- block styles %}
  File "C:\Users\User\Desktop\PythonTest\microblog\app\../templates\base.html", line 66, in block "content"
    {% block app_content %}{% endblock %}
  File "C:\Users\User\Desktop\PythonTest\microblog\app\../templates\login.html", line 15, in block "app_content"
    <a href="{{ url_for('reset_password_request') }}">Click to Reset It</a>
  File "C:\Users\User\Anaconda3\envs\vnev\lib\site-packages\flask\helpers.py", line 370, in url_for
    return appctx.app.handle_url_build_error(error, endpoint, values)
  File "C:\Users\User\Anaconda3\envs\vnev\lib\site-packages\flask\app.py", line 2215, in handle_url_build_error
    reraise(exc_type, exc_value, tb)
  File "C:\Users\User\Anaconda3\envs\vnev\lib\site-packages\flask\_compat.py", line 39, in reraise
    raise value
  File "C:\Users\User\Anaconda3\envs\vnev\lib\site-packages\flask\helpers.py", line 358, in url_for
    endpoint, values, method=method, force_external=external
  File "C:\Users\User\Anaconda3\envs\vnev\lib\site-packages\werkzeug\routing.py", line 2179, in build
    raise BuildError(endpoint, values, method, self)
werkzeug.routing.BuildError: Could not build url for endpoint 'reset_password_request'. Did you mean 'edit_profile' instead?
2020-04-25 16:52:16,673 ERROR: Exception on /login [GET] [in C:\Users\User\Anaconda3\envs\vnev\lib\site-packages\flask\app.py:1891]
Traceback (most recent call last):
  File "C:\Users\User\Anaconda3\envs\vnev\lib\site-packages\flask\app.py", line 2446, in wsgi_app
    response = self.full_dispatch_request()
  File "C:\Users\User\Anaconda3\envs\vnev\lib\site-packages\flask\app.py", line 1951, in full_dispatch_request
    rv = self.handle_user_exception(e)
  File "C:\Users\User\Anaconda3\envs\vnev\lib\site-packages\flask\app.py", line 1820, in handle_user_exception
    reraise(exc_type, exc_value, tb)
  File "C:\Users\User\Anaconda3\envs\vnev\lib\site-packages\flask\_compat.py", line 39, in reraise
    raise value
  File "C:\Users\User\Anaconda3\envs\vnev\lib\site-packages\flask\app.py", line 1949, in full_dispatch_request
    rv = self.dispatch_request()
  File "C:\Users\User\Anaconda3\envs\vnev\lib\site-packages\flask\app.py", line 1935, in dispatch_request
    return self.view_functions[rule.endpoint](**req.view_args)
  File "C:\Users\User\Desktop\PythonTest\microblog\app\routes.py", line 58, in login
    return render_template('login.html',title='SignIn',form=form)
  File "C:\Users\User\Anaconda3\envs\vnev\lib\site-packages\flask\templating.py", line 140, in render_template
    ctx.app,
  File "C:\Users\User\Anaconda3\envs\vnev\lib\site-packages\flask\templating.py", line 120, in _render
    rv = template.render(context)
  File "C:\Users\User\Anaconda3\envs\vnev\lib\site-packages\jinja2\environment.py", line 1090, in render
    self.environment.handle_exception()
  File "C:\Users\User\Anaconda3\envs\vnev\lib\site-packages\jinja2\environment.py", line 832, in handle_exception
    reraise(*rewrite_traceback_stack(source=source))
  File "C:\Users\User\Anaconda3\envs\vnev\lib\site-packages\jinja2\_compat.py", line 28, in reraise
    raise value.with_traceback(tb)
  File "C:\Users\User\Desktop\PythonTest\microblog\app\../templates\login.html", line 2, in top-level template code
    {% import 'bootstrap/wtf.html' as wtf %}
  File "C:\Users\User\Desktop\PythonTest\microblog\app\../templates\base.html", line 1, in top-level template code
    {% extends 'bootstrap/base.html' %}
  File "C:\Users\User\Anaconda3\envs\vnev\lib\site-packages\flask_bootstrap\templates\bootstrap\base.html", line 1, in top-level template code
    {% block doc -%}
  File "C:\Users\User\Anaconda3\envs\vnev\lib\site-packages\flask_bootstrap\templates\bootstrap\base.html", line 3, in block "doc"
    <html{% block html_attribs %}{% endblock html_attribs %}>
  File "C:\Users\User\Anaconda3\envs\vnev\lib\site-packages\flask_bootstrap\templates\bootstrap\base.html", line 11, in block "html"
    {%- endblock metas %}
  File "C:\Users\User\Anaconda3\envs\vnev\lib\site-packages\flask_bootstrap\templates\bootstrap\base.html", line 13, in block "body"
    {%- block styles %}
  File "C:\Users\User\Desktop\PythonTest\microblog\app\../templates\base.html", line 66, in block "content"
    {% block app_content %}{% endblock %}
  File "C:\Users\User\Desktop\PythonTest\microblog\app\../templates\login.html", line 15, in block "app_content"
    <a href="{{ url_for('reset_password_request') }}">Click to Reset It</a>
  File "C:\Users\User\Anaconda3\envs\vnev\lib\site-packages\flask\helpers.py", line 370, in url_for
    return appctx.app.handle_url_build_error(error, endpoint, values)
  File "C:\Users\User\Anaconda3\envs\vnev\lib\site-packages\flask\app.py", line 2215, in handle_url_build_error
    reraise(exc_type, exc_value, tb)
  File "C:\Users\User\Anaconda3\envs\vnev\lib\site-packages\flask\_compat.py", line 39, in reraise
    raise value
  File "C:\Users\User\Anaconda3\envs\vnev\lib\site-packages\flask\helpers.py", line 358, in url_for
    endpoint, values, method=method, force_external=external
  File "C:\Users\User\Anaconda3\envs\vnev\lib\site-packages\werkzeug\routing.py", line 2179, in build
    raise BuildError(endpoint, values, method, self)
werkzeug.routing.BuildError: Could not build url for endpoint 'reset_password_request'. Did you mean 'edit_profile' instead?
